2021-09-06 06:26:48,453 11017 INFO ? flectra: Flectra version 2.0 
2021-09-06 06:26:48,453 11017 INFO ? flectra: Using configuration file at /home/admin/.flectrarc 
2021-09-06 06:26:48,453 11017 INFO ? flectra: addons paths: ['/home/admin/flectra2/flectra/flectra/addons', '/home/admin/.local/share/Flectra/addons/2.0', '/home/admin/flectra2/flectra/addons'] 
2021-09-06 06:26:48,454 11017 INFO ? flectra: database: default@default:default 
2021-09-06 06:26:48,604 11017 INFO ? flectra.addons.base.models.ir_actions_report: Will use the Wkhtmltopdf binary at /usr/local/bin/wkhtmltopdf 
2021-09-06 06:26:48,700 11017 INFO ? flectra.service.server: HTTP service (werkzeug) running on i-a2dizi6jhmk8dnkivs74:7073 
2021-09-06 06:27:00,663 11017 INFO ? flectra.http: HTTP Configuring static files 
2021-09-06 06:27:00,671 11017 INFO ? flectra.http: Generating nondb routing 
2021-09-06 06:27:00,698 11017 INFO ? werkzeug: 175.157.102.149 - - [06/Sep/2021 06:27:00] "GET /web HTTP/1.1" 303 - 2 0.003 0.029
2021-09-06 06:27:01,070 11017 INFO ? flectra.sql_db: ConnectionPool(used=0/count=1/max=64): Closed 1 connections to 'sslmode=prefer dbname=odoo' 
2021-09-06 06:27:01,094 11017 INFO ? werkzeug: 175.157.102.149 - - [06/Sep/2021 06:27:01] "GET /web/database/selector HTTP/1.1" 200 - 6 0.008 0.077
2021-09-06 06:38:18,338 11017 INFO ? flectra.service.server: Initiating shutdown 
2021-09-06 06:38:18,338 11017 INFO ? flectra.service.server: Hit CTRL-C again or send a second signal to force the shutdown. 
2021-09-06 06:38:37,492 11164 INFO ? flectra: Flectra version 2.0 
2021-09-06 06:38:37,492 11164 INFO ? flectra: Using configuration file at /home/admin/.flectrarc 
2021-09-06 06:38:37,492 11164 INFO ? flectra: addons paths: ['/home/admin/flectra2/flectra/flectra/addons', '/home/admin/.local/share/Flectra/addons/2.0', '/home/admin/flectra2/flectra/addons'] 
2021-09-06 06:38:37,492 11164 INFO ? flectra: database: flectra2@default:default 
2021-09-06 06:38:37,643 11164 INFO ? flectra.addons.base.models.ir_actions_report: Will use the Wkhtmltopdf binary at /usr/local/bin/wkhtmltopdf 
2021-09-06 06:38:37,747 11164 INFO ? flectra.service.server: HTTP service (werkzeug) running on i-a2dizi6jhmk8dnkivs74:7073 
2021-09-06 06:38:46,772 11164 INFO ? flectra.http: HTTP Configuring static files 
2021-09-06 06:38:46,779 11164 INFO ? flectra.sql_db: Connection to the database failed 
2021-09-06 06:38:46,781 11164 INFO ? werkzeug: 175.157.102.149 - - [06/Sep/2021 06:38:46] "GET /web/database/manager HTTP/1.1" 500 - 0 0.000 0.007
2021-09-06 06:38:46,789 11164 ERROR ? werkzeug: Error on request:
Traceback (most recent call last):
  File "/home/admin/flectra2/env/lib/python3.8/site-packages/werkzeug/serving.py", line 306, in run_wsgi
    execute(self.server.app)
  File "/home/admin/flectra2/env/lib/python3.8/site-packages/werkzeug/serving.py", line 294, in execute
    application_iter = app(environ, start_response)
  File "/home/admin/flectra2/flectra/flectra/service/server.py", line 441, in app
    return self.app(e, s)
  File "/home/admin/flectra2/flectra/flectra/service/wsgi_server.py", line 124, in application
    return application_unproxied(environ, start_response)
  File "/home/admin/flectra2/flectra/flectra/service/wsgi_server.py", line 99, in application_unproxied
    result = flectra.http.root(environ, start_response)
  File "/home/admin/flectra2/flectra/flectra/http.py", line 1306, in __call__
    return self.dispatch(environ, start_response)
  File "/home/admin/flectra2/flectra/flectra/http.py", line 1272, in __call__
    return self.app(environ, start_wrapped)
  File "/home/admin/flectra2/env/lib/python3.8/site-packages/werkzeug/middleware/shared_data.py", line 220, in __call__
    return self.app(environ, start_response)
  File "/home/admin/flectra2/flectra/flectra/http.py", line 1440, in dispatch
    self.setup_db(httprequest)
  File "/home/admin/flectra2/flectra/flectra/http.py", line 1363, in setup_db
    httprequest.session.db = db_monodb(httprequest)
  File "/home/admin/flectra2/flectra/flectra/http.py", line 1528, in db_monodb
    dbs = db_list(True, httprequest)
  File "/home/admin/flectra2/flectra/flectra/http.py", line 1495, in db_list
    dbs = flectra.service.db.list_dbs(force)
  File "/home/admin/flectra2/flectra/flectra/service/db.py", line 384, in list_dbs
    with closing(db.cursor()) as cr:
  File "/home/admin/flectra2/flectra/flectra/sql_db.py", line 675, in cursor
    return Cursor(self.__pool, self.dbname, self.dsn, serialized=serialized)
  File "/home/admin/flectra2/flectra/flectra/sql_db.py", line 248, in __init__
    self._cnx = pool.borrow(dsn)
  File "/home/admin/flectra2/flectra/flectra/sql_db.py", line 558, in _locked
    return fun(self, *args, **kwargs)
  File "/home/admin/flectra2/flectra/flectra/sql_db.py", line 624, in borrow
    result = psycopg2.connect(
  File "/home/admin/flectra2/env/lib/python3.8/site-packages/psycopg2/__init__.py", line 127, in connect
    conn = _connect(dsn, connection_factory=connection_factory, **kwasync)
psycopg2.OperationalError: FATAL:  Peer authentication failed for user "flectra2" - - -
2021-09-06 06:38:47,158 11164 INFO ? flectra.sql_db: Connection to the database failed 
2021-09-06 06:38:47,160 11164 INFO ? werkzeug: 175.157.102.149 - - [06/Sep/2021 06:38:47] "GET /favicon.ico HTTP/1.1" 500 - 0 0.000 0.008
2021-09-06 06:38:47,166 11164 ERROR ? werkzeug: Error on request:
Traceback (most recent call last):
  File "/home/admin/flectra2/env/lib/python3.8/site-packages/werkzeug/serving.py", line 306, in run_wsgi
    execute(self.server.app)
  File "/home/admin/flectra2/env/lib/python3.8/site-packages/werkzeug/serving.py", line 294, in execute
    application_iter = app(environ, start_response)
  File "/home/admin/flectra2/flectra/flectra/service/server.py", line 441, in app
    return self.app(e, s)
  File "/home/admin/flectra2/flectra/flectra/service/wsgi_server.py", line 124, in application
    return application_unproxied(environ, start_response)
  File "/home/admin/flectra2/flectra/flectra/service/wsgi_server.py", line 99, in application_unproxied
    result = flectra.http.root(environ, start_response)
  File "/home/admin/flectra2/flectra/flectra/http.py", line 1306, in __call__
    return self.dispatch(environ, start_response)
  File "/home/admin/flectra2/flectra/flectra/http.py", line 1272, in __call__
    return self.app(environ, start_wrapped)
  File "/home/admin/flectra2/env/lib/python3.8/site-packages/werkzeug/middleware/shared_data.py", line 220, in __call__
    return self.app(environ, start_response)
  File "/home/admin/flectra2/flectra/flectra/http.py", line 1440, in dispatch
    self.setup_db(httprequest)
  File "/home/admin/flectra2/flectra/flectra/http.py", line 1363, in setup_db
    httprequest.session.db = db_monodb(httprequest)
  File "/home/admin/flectra2/flectra/flectra/http.py", line 1528, in db_monodb
    dbs = db_list(True, httprequest)
  File "/home/admin/flectra2/flectra/flectra/http.py", line 1495, in db_list
    dbs = flectra.service.db.list_dbs(force)
  File "/home/admin/flectra2/flectra/flectra/service/db.py", line 384, in list_dbs
    with closing(db.cursor()) as cr:
  File "/home/admin/flectra2/flectra/flectra/sql_db.py", line 675, in cursor
    return Cursor(self.__pool, self.dbname, self.dsn, serialized=serialized)
  File "/home/admin/flectra2/flectra/flectra/sql_db.py", line 248, in __init__
    self._cnx = pool.borrow(dsn)
  File "/home/admin/flectra2/flectra/flectra/sql_db.py", line 558, in _locked
    return fun(self, *args, **kwargs)
  File "/home/admin/flectra2/flectra/flectra/sql_db.py", line 624, in borrow
    result = psycopg2.connect(
  File "/home/admin/flectra2/env/lib/python3.8/site-packages/psycopg2/__init__.py", line 127, in connect
    conn = _connect(dsn, connection_factory=connection_factory, **kwasync)
psycopg2.OperationalError: FATAL:  Peer authentication failed for user "flectra2" - - -
2021-09-06 06:38:53,803 11164 INFO ? flectra.sql_db: Connection to the database failed 
2021-09-06 06:38:53,805 11164 INFO ? werkzeug: 175.157.102.149 - - [06/Sep/2021 06:38:53] "GET /web/database/manager HTTP/1.1" 500 - 0 0.000 0.007
2021-09-06 06:38:53,811 11164 ERROR ? werkzeug: Error on request:
Traceback (most recent call last):
  File "/home/admin/flectra2/env/lib/python3.8/site-packages/werkzeug/serving.py", line 306, in run_wsgi
    execute(self.server.app)
  File "/home/admin/flectra2/env/lib/python3.8/site-packages/werkzeug/serving.py", line 294, in execute
    application_iter = app(environ, start_response)
  File "/home/admin/flectra2/flectra/flectra/service/server.py", line 441, in app
    return self.app(e, s)
  File "/home/admin/flectra2/flectra/flectra/service/wsgi_server.py", line 124, in application
    return application_unproxied(environ, start_response)
  File "/home/admin/flectra2/flectra/flectra/service/wsgi_server.py", line 99, in application_unproxied
    result = flectra.http.root(environ, start_response)
  File "/home/admin/flectra2/flectra/flectra/http.py", line 1306, in __call__
    return self.dispatch(environ, start_response)
  File "/home/admin/flectra2/flectra/flectra/http.py", line 1272, in __call__
    return self.app(environ, start_wrapped)
  File "/home/admin/flectra2/env/lib/python3.8/site-packages/werkzeug/middleware/shared_data.py", line 220, in __call__
    return self.app(environ, start_response)
  File "/home/admin/flectra2/flectra/flectra/http.py", line 1440, in dispatch
    self.setup_db(httprequest)
  File "/home/admin/flectra2/flectra/flectra/http.py", line 1363, in setup_db
    httprequest.session.db = db_monodb(httprequest)
  File "/home/admin/flectra2/flectra/flectra/http.py", line 1528, in db_monodb
    dbs = db_list(True, httprequest)
  File "/home/admin/flectra2/flectra/flectra/http.py", line 1495, in db_list
    dbs = flectra.service.db.list_dbs(force)
  File "/home/admin/flectra2/flectra/flectra/service/db.py", line 384, in list_dbs
    with closing(db.cursor()) as cr:
  File "/home/admin/flectra2/flectra/flectra/sql_db.py", line 675, in cursor
    return Cursor(self.__pool, self.dbname, self.dsn, serialized=serialized)
  File "/home/admin/flectra2/flectra/flectra/sql_db.py", line 248, in __init__
    self._cnx = pool.borrow(dsn)
  File "/home/admin/flectra2/flectra/flectra/sql_db.py", line 558, in _locked
    return fun(self, *args, **kwargs)
  File "/home/admin/flectra2/flectra/flectra/sql_db.py", line 624, in borrow
    result = psycopg2.connect(
  File "/home/admin/flectra2/env/lib/python3.8/site-packages/psycopg2/__init__.py", line 127, in connect
    conn = _connect(dsn, connection_factory=connection_factory, **kwasync)
psycopg2.OperationalError: FATAL:  Peer authentication failed for user "flectra2" - - -
2021-09-06 06:38:54,175 11164 INFO ? flectra.sql_db: Connection to the database failed 
2021-09-06 06:38:54,180 11164 INFO ? werkzeug: 175.157.102.149 - - [06/Sep/2021 06:38:54] "GET /favicon.ico HTTP/1.1" 500 - 0 0.000 0.010
2021-09-06 06:38:54,183 11164 ERROR ? werkzeug: Error on request:
Traceback (most recent call last):
  File "/home/admin/flectra2/env/lib/python3.8/site-packages/werkzeug/serving.py", line 306, in run_wsgi
    execute(self.server.app)
  File "/home/admin/flectra2/env/lib/python3.8/site-packages/werkzeug/serving.py", line 294, in execute
    application_iter = app(environ, start_response)
  File "/home/admin/flectra2/flectra/flectra/service/server.py", line 441, in app
    return self.app(e, s)
  File "/home/admin/flectra2/flectra/flectra/service/wsgi_server.py", line 124, in application
    return application_unproxied(environ, start_response)
  File "/home/admin/flectra2/flectra/flectra/service/wsgi_server.py", line 99, in application_unproxied
    result = flectra.http.root(environ, start_response)
  File "/home/admin/flectra2/flectra/flectra/http.py", line 1306, in __call__
    return self.dispatch(environ, start_response)
  File "/home/admin/flectra2/flectra/flectra/http.py", line 1272, in __call__
    return self.app(environ, start_wrapped)
  File "/home/admin/flectra2/env/lib/python3.8/site-packages/werkzeug/middleware/shared_data.py", line 220, in __call__
    return self.app(environ, start_response)
  File "/home/admin/flectra2/flectra/flectra/http.py", line 1440, in dispatch
    self.setup_db(httprequest)
  File "/home/admin/flectra2/flectra/flectra/http.py", line 1363, in setup_db
    httprequest.session.db = db_monodb(httprequest)
  File "/home/admin/flectra2/flectra/flectra/http.py", line 1528, in db_monodb
    dbs = db_list(True, httprequest)
  File "/home/admin/flectra2/flectra/flectra/http.py", line 1495, in db_list
    dbs = flectra.service.db.list_dbs(force)
  File "/home/admin/flectra2/flectra/flectra/service/db.py", line 384, in list_dbs
    with closing(db.cursor()) as cr:
  File "/home/admin/flectra2/flectra/flectra/sql_db.py", line 675, in cursor
    return Cursor(self.__pool, self.dbname, self.dsn, serialized=serialized)
  File "/home/admin/flectra2/flectra/flectra/sql_db.py", line 248, in __init__
    self._cnx = pool.borrow(dsn)
  File "/home/admin/flectra2/flectra/flectra/sql_db.py", line 558, in _locked
    return fun(self, *args, **kwargs)
  File "/home/admin/flectra2/flectra/flectra/sql_db.py", line 624, in borrow
    result = psycopg2.connect(
  File "/home/admin/flectra2/env/lib/python3.8/site-packages/psycopg2/__init__.py", line 127, in connect
    conn = _connect(dsn, connection_factory=connection_factory, **kwasync)
psycopg2.OperationalError: FATAL:  Peer authentication failed for user "flectra2" - - -
2021-09-06 06:40:26,917 11199 INFO ? flectra: Flectra version 2.0 
2021-09-06 06:40:26,917 11199 INFO ? flectra: Using configuration file at /home/admin/.flectrarc 
2021-09-06 06:40:26,917 11199 INFO ? flectra: addons paths: ['/home/admin/flectra2/flectra/flectra/addons', '/home/admin/.local/share/Flectra/addons/2.0', '/home/admin/flectra2/flectra/addons'] 
2021-09-06 06:40:26,917 11199 INFO ? flectra: database: flectra2@default:default 
2021-09-06 06:40:27,074 11199 INFO ? flectra.addons.base.models.ir_actions_report: Will use the Wkhtmltopdf binary at /usr/local/bin/wkhtmltopdf 
2021-09-06 06:40:35,881 11164 INFO ? flectra.sql_db: Connection to the database failed 
2021-09-06 06:40:35,883 11164 INFO ? werkzeug: 175.157.102.149 - - [06/Sep/2021 06:40:35] "GET /web/database/manager HTTP/1.1" 500 - 0 0.000 0.006
2021-09-06 06:40:35,886 11164 ERROR ? werkzeug: Error on request:
Traceback (most recent call last):
  File "/home/admin/flectra2/env/lib/python3.8/site-packages/werkzeug/serving.py", line 306, in run_wsgi
    execute(self.server.app)
  File "/home/admin/flectra2/env/lib/python3.8/site-packages/werkzeug/serving.py", line 294, in execute
    application_iter = app(environ, start_response)
  File "/home/admin/flectra2/flectra/flectra/service/server.py", line 441, in app
    return self.app(e, s)
  File "/home/admin/flectra2/flectra/flectra/service/wsgi_server.py", line 124, in application
    return application_unproxied(environ, start_response)
  File "/home/admin/flectra2/flectra/flectra/service/wsgi_server.py", line 99, in application_unproxied
    result = flectra.http.root(environ, start_response)
  File "/home/admin/flectra2/flectra/flectra/http.py", line 1306, in __call__
    return self.dispatch(environ, start_response)
  File "/home/admin/flectra2/flectra/flectra/http.py", line 1272, in __call__
    return self.app(environ, start_wrapped)
  File "/home/admin/flectra2/env/lib/python3.8/site-packages/werkzeug/middleware/shared_data.py", line 220, in __call__
    return self.app(environ, start_response)
  File "/home/admin/flectra2/flectra/flectra/http.py", line 1440, in dispatch
    self.setup_db(httprequest)
  File "/home/admin/flectra2/flectra/flectra/http.py", line 1363, in setup_db
    httprequest.session.db = db_monodb(httprequest)
  File "/home/admin/flectra2/flectra/flectra/http.py", line 1528, in db_monodb
    dbs = db_list(True, httprequest)
  File "/home/admin/flectra2/flectra/flectra/http.py", line 1495, in db_list
    dbs = flectra.service.db.list_dbs(force)
  File "/home/admin/flectra2/flectra/flectra/service/db.py", line 384, in list_dbs
    with closing(db.cursor()) as cr:
  File "/home/admin/flectra2/flectra/flectra/sql_db.py", line 675, in cursor
    return Cursor(self.__pool, self.dbname, self.dsn, serialized=serialized)
  File "/home/admin/flectra2/flectra/flectra/sql_db.py", line 248, in __init__
    self._cnx = pool.borrow(dsn)
  File "/home/admin/flectra2/flectra/flectra/sql_db.py", line 558, in _locked
    return fun(self, *args, **kwargs)
  File "/home/admin/flectra2/flectra/flectra/sql_db.py", line 624, in borrow
    result = psycopg2.connect(
  File "/home/admin/flectra2/env/lib/python3.8/site-packages/psycopg2/__init__.py", line 127, in connect
    conn = _connect(dsn, connection_factory=connection_factory, **kwasync)
psycopg2.OperationalError: FATAL:  Peer authentication failed for user "flectra2" - - -
2021-09-06 06:40:36,299 11164 INFO ? flectra.sql_db: Connection to the database failed 
2021-09-06 06:40:36,301 11164 INFO ? werkzeug: 175.157.102.149 - - [06/Sep/2021 06:40:36] "GET /favicon.ico HTTP/1.1" 500 - 0 0.000 0.006
2021-09-06 06:40:36,305 11164 ERROR ? werkzeug: Error on request:
Traceback (most recent call last):
  File "/home/admin/flectra2/env/lib/python3.8/site-packages/werkzeug/serving.py", line 306, in run_wsgi
    execute(self.server.app)
  File "/home/admin/flectra2/env/lib/python3.8/site-packages/werkzeug/serving.py", line 294, in execute
    application_iter = app(environ, start_response)
  File "/home/admin/flectra2/flectra/flectra/service/server.py", line 441, in app
    return self.app(e, s)
  File "/home/admin/flectra2/flectra/flectra/service/wsgi_server.py", line 124, in application
    return application_unproxied(environ, start_response)
  File "/home/admin/flectra2/flectra/flectra/service/wsgi_server.py", line 99, in application_unproxied
    result = flectra.http.root(environ, start_response)
  File "/home/admin/flectra2/flectra/flectra/http.py", line 1306, in __call__
    return self.dispatch(environ, start_response)
  File "/home/admin/flectra2/flectra/flectra/http.py", line 1272, in __call__
    return self.app(environ, start_wrapped)
  File "/home/admin/flectra2/env/lib/python3.8/site-packages/werkzeug/middleware/shared_data.py", line 220, in __call__
    return self.app(environ, start_response)
  File "/home/admin/flectra2/flectra/flectra/http.py", line 1440, in dispatch
    self.setup_db(httprequest)
  File "/home/admin/flectra2/flectra/flectra/http.py", line 1363, in setup_db
    httprequest.session.db = db_monodb(httprequest)
  File "/home/admin/flectra2/flectra/flectra/http.py", line 1528, in db_monodb
    dbs = db_list(True, httprequest)
  File "/home/admin/flectra2/flectra/flectra/http.py", line 1495, in db_list
    dbs = flectra.service.db.list_dbs(force)
  File "/home/admin/flectra2/flectra/flectra/service/db.py", line 384, in list_dbs
    with closing(db.cursor()) as cr:
  File "/home/admin/flectra2/flectra/flectra/sql_db.py", line 675, in cursor
    return Cursor(self.__pool, self.dbname, self.dsn, serialized=serialized)
  File "/home/admin/flectra2/flectra/flectra/sql_db.py", line 248, in __init__
    self._cnx = pool.borrow(dsn)
  File "/home/admin/flectra2/flectra/flectra/sql_db.py", line 558, in _locked
    return fun(self, *args, **kwargs)
  File "/home/admin/flectra2/flectra/flectra/sql_db.py", line 624, in borrow
    result = psycopg2.connect(
  File "/home/admin/flectra2/env/lib/python3.8/site-packages/psycopg2/__init__.py", line 127, in connect
    conn = _connect(dsn, connection_factory=connection_factory, **kwasync)
psycopg2.OperationalError: FATAL:  Peer authentication failed for user "flectra2" - - -
2021-09-06 06:40:48,367 11164 INFO ? flectra.service.server: Initiating shutdown 
2021-09-06 06:40:48,367 11164 INFO ? flectra.service.server: Hit CTRL-C again or send a second signal to force the shutdown. 
2021-09-06 06:40:48,367 11199 INFO ? flectra.service.server: Initiating shutdown 
2021-09-06 06:40:48,367 11199 INFO ? flectra.service.server: Hit CTRL-C again or send a second signal to force the shutdown. 
2021-09-06 06:40:50,790 11213 INFO ? flectra: Flectra version 2.0 
2021-09-06 06:40:50,791 11213 INFO ? flectra: Using configuration file at /home/admin/.flectrarc 
2021-09-06 06:40:50,791 11213 INFO ? flectra: addons paths: ['/home/admin/flectra2/flectra/flectra/addons', '/home/admin/.local/share/Flectra/addons/2.0', '/home/admin/flectra2/flectra/addons'] 
2021-09-06 06:40:50,791 11213 INFO ? flectra: database: flectra2@default:default 
2021-09-06 06:40:50,927 11213 INFO ? flectra.addons.base.models.ir_actions_report: Will use the Wkhtmltopdf binary at /usr/local/bin/wkhtmltopdf 
2021-09-06 06:40:51,038 11213 INFO ? flectra.service.server: HTTP service (werkzeug) running on i-a2dizi6jhmk8dnkivs74:7073 
2021-09-06 06:40:54,023 11164 INFO ? flectra.sql_db: Connection to the database failed 
2021-09-06 06:40:54,025 11164 INFO ? werkzeug: 175.157.102.149 - - [06/Sep/2021 06:40:54] "GET /web/database/manager HTTP/1.1" 500 - 0 0.000 0.006
2021-09-06 06:40:54,030 11164 ERROR ? werkzeug: Error on request:
Traceback (most recent call last):
  File "/home/admin/flectra2/env/lib/python3.8/site-packages/werkzeug/serving.py", line 306, in run_wsgi
    execute(self.server.app)
  File "/home/admin/flectra2/env/lib/python3.8/site-packages/werkzeug/serving.py", line 294, in execute
    application_iter = app(environ, start_response)
  File "/home/admin/flectra2/flectra/flectra/service/server.py", line 441, in app
    return self.app(e, s)
  File "/home/admin/flectra2/flectra/flectra/service/wsgi_server.py", line 124, in application
    return application_unproxied(environ, start_response)
  File "/home/admin/flectra2/flectra/flectra/service/wsgi_server.py", line 99, in application_unproxied
    result = flectra.http.root(environ, start_response)
  File "/home/admin/flectra2/flectra/flectra/http.py", line 1306, in __call__
    return self.dispatch(environ, start_response)
  File "/home/admin/flectra2/flectra/flectra/http.py", line 1272, in __call__
    return self.app(environ, start_wrapped)
  File "/home/admin/flectra2/env/lib/python3.8/site-packages/werkzeug/middleware/shared_data.py", line 220, in __call__
    return self.app(environ, start_response)
  File "/home/admin/flectra2/flectra/flectra/http.py", line 1440, in dispatch
    self.setup_db(httprequest)
  File "/home/admin/flectra2/flectra/flectra/http.py", line 1363, in setup_db
    httprequest.session.db = db_monodb(httprequest)
  File "/home/admin/flectra2/flectra/flectra/http.py", line 1528, in db_monodb
    dbs = db_list(True, httprequest)
  File "/home/admin/flectra2/flectra/flectra/http.py", line 1495, in db_list
    dbs = flectra.service.db.list_dbs(force)
  File "/home/admin/flectra2/flectra/flectra/service/db.py", line 384, in list_dbs
    with closing(db.cursor()) as cr:
  File "/home/admin/flectra2/flectra/flectra/sql_db.py", line 675, in cursor
    return Cursor(self.__pool, self.dbname, self.dsn, serialized=serialized)
  File "/home/admin/flectra2/flectra/flectra/sql_db.py", line 248, in __init__
    self._cnx = pool.borrow(dsn)
  File "/home/admin/flectra2/flectra/flectra/sql_db.py", line 558, in _locked
    return fun(self, *args, **kwargs)
  File "/home/admin/flectra2/flectra/flectra/sql_db.py", line 624, in borrow
    result = psycopg2.connect(
  File "/home/admin/flectra2/env/lib/python3.8/site-packages/psycopg2/__init__.py", line 127, in connect
    conn = _connect(dsn, connection_factory=connection_factory, **kwasync)
psycopg2.OperationalError: FATAL:  Peer authentication failed for user "flectra2" - - -
2021-09-06 06:40:54,432 11213 INFO ? flectra.http: HTTP Configuring static files 
2021-09-06 06:40:54,439 11213 INFO ? flectra.sql_db: Connection to the database failed 
2021-09-06 06:40:54,441 11213 INFO ? werkzeug: 175.157.102.149 - - [06/Sep/2021 06:40:54] "GET /favicon.ico HTTP/1.1" 500 - 0 0.000 0.007
2021-09-06 06:40:54,446 11213 ERROR ? werkzeug: Error on request:
Traceback (most recent call last):
  File "/home/admin/flectra2/env/lib/python3.8/site-packages/werkzeug/serving.py", line 306, in run_wsgi
    execute(self.server.app)
  File "/home/admin/flectra2/env/lib/python3.8/site-packages/werkzeug/serving.py", line 294, in execute
    application_iter = app(environ, start_response)
  File "/home/admin/flectra2/flectra/flectra/service/server.py", line 441, in app
    return self.app(e, s)
  File "/home/admin/flectra2/flectra/flectra/service/wsgi_server.py", line 124, in application
    return application_unproxied(environ, start_response)
  File "/home/admin/flectra2/flectra/flectra/service/wsgi_server.py", line 99, in application_unproxied
    result = flectra.http.root(environ, start_response)
  File "/home/admin/flectra2/flectra/flectra/http.py", line 1306, in __call__
    return self.dispatch(environ, start_response)
  File "/home/admin/flectra2/flectra/flectra/http.py", line 1272, in __call__
    return self.app(environ, start_wrapped)
  File "/home/admin/flectra2/env/lib/python3.8/site-packages/werkzeug/middleware/shared_data.py", line 220, in __call__
    return self.app(environ, start_response)
  File "/home/admin/flectra2/flectra/flectra/http.py", line 1440, in dispatch
    self.setup_db(httprequest)
  File "/home/admin/flectra2/flectra/flectra/http.py", line 1363, in setup_db
    httprequest.session.db = db_monodb(httprequest)
  File "/home/admin/flectra2/flectra/flectra/http.py", line 1528, in db_monodb
    dbs = db_list(True, httprequest)
  File "/home/admin/flectra2/flectra/flectra/http.py", line 1495, in db_list
    dbs = flectra.service.db.list_dbs(force)
  File "/home/admin/flectra2/flectra/flectra/service/db.py", line 384, in list_dbs
    with closing(db.cursor()) as cr:
  File "/home/admin/flectra2/flectra/flectra/sql_db.py", line 675, in cursor
    return Cursor(self.__pool, self.dbname, self.dsn, serialized=serialized)
  File "/home/admin/flectra2/flectra/flectra/sql_db.py", line 248, in __init__
    self._cnx = pool.borrow(dsn)
  File "/home/admin/flectra2/flectra/flectra/sql_db.py", line 558, in _locked
    return fun(self, *args, **kwargs)
  File "/home/admin/flectra2/flectra/flectra/sql_db.py", line 624, in borrow
    result = psycopg2.connect(
  File "/home/admin/flectra2/env/lib/python3.8/site-packages/psycopg2/__init__.py", line 127, in connect
    conn = _connect(dsn, connection_factory=connection_factory, **kwasync)
psycopg2.OperationalError: FATAL:  Peer authentication failed for user "flectra2" - - -
2021-09-06 06:42:25,828 11213 INFO ? flectra.service.server: Initiating shutdown 
2021-09-06 06:42:25,828 11213 INFO ? flectra.service.server: Hit CTRL-C again or send a second signal to force the shutdown. 
